Workbook
Name _Check.Y.N: [3]Lists!$A$1:$A$2
Name AssetsList: [4]Assets!$A$2:$A$50
Name AssetsList: 'Assets (2)'!$A$2:$A$500
Name AssetsList: 'Asset-types (check)'!$A$2:$A$53
Name Consolidated_Threat_Hazard_Categories: '[1]Key Risks'!$A$2:$A$21
Name Dept.or.Function: '[5]Lookup lists'!$A$2:$A$21
Name DocList: #REF!
Name DocsList: '[4]Master list'!$E$2:$E$39
Name DocsList: #REF!
Name ISMSrecords: #REF!
Name KontroleID: Controls!$A$3:$A$116
Name LikelihoodRating: [4]Likelihood!$A$2:$A$6
Name LikelihoodRating: Likelihood!$A$2:$A$6
Name ListaPrijetnji: Threats!$B$5:$B$52
Name ListaPrijetnji2: Threats!$B$5:$B$62
Name Opcije: 'RTP Options'!$A$2:$A$5
Name Options: [2]Options!$A$3:$A$6
Name Options2: 'RTP Options'!$A$9:$A$12
Name Prijetnja: Threats!$B$5:$B$52
Name Prijetnja: Threats!$B$5:$B$52
Name RatingAvailability: [4]Impact!$A$19:$A$23
Name RatingAvailability: Impact!$A$19:$A$23
Name RatingConfidentiality: [4]Impact!$A$3:$A$7
Name RatingConfidentiality: Impact!$A$3:$A$7
Name RatingIntegrity: [4]Impact!$A$11:$A$15
Name RatingIntegrity: Impact!$A$11:$A$15
Name RiskOwners: [4]Owners!$B$2:$B$20
Name RiskOwners: Owners!$B$2:$B$20
Name RTPoptions: '[4]RTP Options'!$A$2:$A$12
Name RTPoptions: 'RTP Options'!$A$2:$A$12
Name RTPstatus: '[4]RTP status'!$A$2:$A$17
Name RTPstatus: 'RTP status'!$A$2:$A$17
Name ThreatsList: [4]Threats!$B$5:$B$197
Name ThreatsList: Threats!$B$5:$B$197
Name Vulberability2: #REF!
Name Vulberability2: #REF!
Name Vulberability2: #REF!
Name Vulberability2: #REF!
Name Vulberability2: #REF!
Name Vulberability2: #REF!
Name VulnerabitiesList: [4]Vulnerabilities!$B$6:$B$300
Name VulnerabitiesList: Vulnerabilities!$B$6:$B$300

Sheet Cover
B9: Company | C9: Agile Lab Pte Ltd
B10: Department
B11: Address | C11: 73 Ayer Rajah Crescent, #02-28, Singapore 139952
B12: Document Title | C12: ISMS Risk Assessment & Treatment Plan
B13: Standard | C13: ISO27001 | D13: Doc. No. | E13: NA
B14: Classification | C14: Confidential | D14: Rev. No. | E14: 0
B15: Prepared by | C15: Lim Sek Seong & Daniel Lim | D15: Date | E15: 44104
B16: Approved by | D16: Date | E16: =DATE(YEAR(E15),MONTH(E15),DAY(E15)+14) -> 44118

Sheet RA-RTP (Aug2019) (2)
A1: Risk Assessment | N1: Risk Treatment Plan
A2: No | B2: Asset name Asset type | C2: Asset owner | D2: Threat | E2: Vulnerability | F2: Risk owner | G2: Confiden-tiality | H2: Integrity | I2: Availability | J2: Impact Severity | K2: Likelihood | L2: Risk | M2: Existing controls | N2: Selection of options | O2: Implementation approach | P2: By Whom | Q2: Status | R2: Next Follow-up date
A3: 1 | B3: Email server (service) | C3: PD | D3: hacking or virus attack | E3: Confidential information will available to unauthorized persons Email records or data may be modified (loss of data integrity) Email application service and database may be disrupted (unavailable) | F3: PD | G3: 5 | H3: 5 | I3: 5 | J3: =IF(MAX(G3:I3)=0,"",MAX(G3:I3)) -> 5 | K3: 1 | L3: =IFERROR(J3*K3,"") -> 5 | M3: Anti-virus installed and regular updates for virus signatures and application upgrades. | N3: Selection of controls | O3: Conduct VAPT; determine and close weaknesses (if any) | P3: ASP | Q3: Implemented | R3: 43739
D4: application errors | E4: inadequate change control | F4: =IF($C4<>"",C4,"") | G4: 1 | H4: 1 | I4: 5 | J4: =IF(MAX(G4:I4)=0,"",MAX(G4:I4)) -> 5 | K4: 1 | L4: =IFERROR(J4*K4,"") -> 5 | M4: Critical updates and patches are tested by the vendor; then they are applied to the email server. | N4: Selection of controls | O4: Secure Development Policy (ISMS-07) | Q4: Implemented
D5: equipment failure | E5: inadequate maintenance | F5: =IF($C5<>"",C5,"") | G5: 1 | H5: 1 | I5: 5 | J5: =IF(MAX(G5:I5)=0,"",MAX(G5:I5)) -> 5 | K5: 1 | L5: =IFERROR(J5*K5,"") -> 5 | M5: Regular maintenance on essential IT and technology equipment. Implement ICT DR server for email. | N5: Selection of controls | O5: Operating Procedures for Information and Communication Technology (ISMS-14) | Q5: Implemented
D6: equipment failure | E6: location sensitive to water leakage | G6: 1 | H6: 1 | I6: 5 | J6: =IF(MAX(G6:I6)=0,"",MAX(G6:I6)) -> 5 | K6: 1 | L6: =IFERROR(J6*K6,"") -> 5 | M6: Ensure server rooms do not have water pipes running through or near by the server room; except fire protection system that is approved for data centre operations. | N6: Selection of controls | O6: Operating Procedures for Information and Communication Technology (ISMS-14) | Q6: Implemented
D7: equipment failure | E7: sensitivity of equipment to temperature | G7: 1 | H7: 1 | I7: 5 | J7: =IF(MAX(G7:I7)=0,"",MAX(G7:I7)) -> 5 | K7: 1 | L7: =IFERROR(J7*K7,"") -> 5 | M7: Computer server rooms have adequate air-conditioning units operating 24/7 daily. | N7: Selection of controls | O7: Operating Procedures for Information and Communication Technology (ISMS-14) | Q7: Implemented
D8: equipment failure | E8: sensitivity of equipment to voltage change | G8: 1 | H8: 1 | I8: 5 | J8: =IF(MAX(G8:I8)=0,"",MAX(G8:I8)) -> 5 | K8: 1 | L8: =IFERROR(J8*K8,"") -> 5 | M8: Power supply to racks are supplied by circuits with power stabilizers and controllers that are suitable to support data centre electrical power systems. | N8: Selection of controls | O8: Operating Procedures for Information and Communication Technology (ISMS-14) | Q8: Implemented
D9: fire | E9: location sensitive to natural disasters | F9: =IF($C9<>"",C9,"") | G9: 1 | H9: 1 | I9: 5 | J9: =IF(MAX(G9:I9)=0,"",MAX(G9:I9)) -> 5 | K9: 1 | L9: =IFERROR(J9*K9,"") -> 5 | M9: Fire protection systems are implemented and maintained according to FSB requirements; including placement of fire extinguishers and hose reels in selected areas. Servers in the data centre are protected by gas and water fire suppression protection systems. | N9: Risk acceptance | O9: Risk Assessment and Treatment Methodology (ISMS-02) | Q9: Annual review
D10: interruption of power supply | E10: sensitivity of equipment to voltage change | F10: =IF($C10<>"",C10,"") | G10: 1 | H10: 1 | I10: 5 | J10: =IF(MAX(G10:I10)=0,"",MAX(G10:I10)) -> 5 | K10: 1 | L10: =IFERROR(J10*K10,"") -> 5 | M10: Building electrical power supply system and sources are reliable. Data centre also has backup generator and UPS systems to prevent blackouts. | N10: Risk acceptance | O10: Risk Assessment and Treatment Methodology (ISMS-02) | Q10: Annual review
D11: misuse of information systems | E11: inadequate level of knowledge and/or awareness of employees | F11: =IF($C11<>"",C11,"") | G11: 5 | H11: 1 | I11: 1 | J11: =IF(MAX(G11:I11)=0,"",MAX(G11:I11)) -> 5 | K11: 1 | L11: =IFERROR(J11*K11,"") -> 5 | M11: Adequate IS policy, procedures and controls are implemented – staff will be trained be made more aware of IS and cyberattacks. | N11: Selection of controls | O11: Information Security Policy (ISMS-01) | Q11: Implemented
D12: misuse of information systems | E12: inadequate supervision of external suppliers | F12: =IF($C12<>"",C12,"") | G12: 5 | H12: 5 | I12: 5 | J12: =IF(MAX(G12:I12)=0,"",MAX(G12:I12)) -> 5 | K12: 1 | L12: =IFERROR(J12*K12,"") -> 5 | M12: Adequate IS policy, procedures and controls are implemented. Only pre-authorised technicians, engineers and other staff will be granted access to sensitive areas. | N12: Selection of controls | O12: Supplier Security Policy (ISMS-08) | Q12: Implemented
D13: deterioration of media | E13: email records may be lost or corrupted | F13: =IF($C13<>"",C13,"") | G13: 1 | H13: 1 | I13: 5 | J13: =IF(MAX(G13:I13)=0,"",MAX(G13:I13)) -> 5 | K13: 1 | L13: =IFERROR(J13*K13,"") -> 5 | M13: Storage for email records use RAID. Users are required to save critical information and files in the department shared folders. | N13: Selection of controls | O13: Operating Procedures for Information and Communication Technology (ISMS-14) | Q13: Implemented
D14: information interception | E14: Confidential information will available to unauthorized persons. Email records or data may be modified (loss of data integrity). Information obtained may be used to commit fraud or crimes. Stolen intellectual property may be used against the company or disadvantage the company in business deals. | F14: =IF($C14<>"",C14,"") | G14: 5 | H14: 5 | I14: 1 | J14: =IF(MAX(G14:I14)=0,"",MAX(G14:I14)) -> 5 | K14: 1 | L14: =IFERROR(J14*K14,"") -> 5 | M14: Confidential information and intellectual property transmitted file attachments in emails will be encrypted using standard zip tools with passwords; which will be transmitted separately. | N14: Selection of controls | O14: Policy on the Use of Cryptographic Controls (ISMS-09) | Q14: Implemented
A15: 2 | B15: ERP service | C15: PD | D15: hacking or virus attack | E15: Sensitive information about the business will be available to unauthorized persons. Customer and transaction records and data may be lost or leaked. Hackers may seize control of the server system or data records, and use it to commit computer fraud or crime. The system configuration and database may also be damaged or destroyed (loss). | F15: PD | G15: 5 | H15: 5 | I15: 5 | J15: =IF(MAX(G15:I15)=0,"",MAX(G15:I15)) -> 5 | K15: 1 | L15: =IFERROR(J15*K15,"") -> 5 | M15: Anti-virus installed and regular updates for virus signatures and application upgrades. PCs are connected via a dedicated OA network. Users working externally will connect using VPN and https services. Users and administrators (including service provider support staff) access are granted based on least privileged use policy and procedures. | N15: Selection of controls | O15: Procedures for Working in Secure Areas (ISMS-12) | P15: ASP | Q15: Implemented
D16: equipment failure | E16: inadequate maintenance | F16: =IF($C16<>"",C16,"") | G16: 1 | H16: 1 | I16: 5 | J16: =IF(MAX(G16:I16)=0,"",MAX(G16:I16)) -> 5 | K16: 1 | L16: =IFERROR(J16*K16,"") -> 5 | M16: Regular maintenance is carried out on the server hardware and operating system. | N16: Selection of controls | O16: Operating Procedures for Information and Communication Technology (ISMS-14) | Q16: Implemented
D17: equipment failure | E17: location sensitive to water leakage | G17: 1 | H17: 1 | I17: 5 | J17: =IF(MAX(G17:I17)=0,"",MAX(G17:I17)) -> 5 | K17: 1 | L17: =IFERROR(J17*K17,"") -> 5 | M17: Server is located in a secure third party data centre; i.e. no piping inside or around the area. | N17: Selection of controls | O17: Operating Procedures for Information and Communication Technology (ISMS-14) | Q17: Implemented
D18: equipment failure | E18: sensitivity of equipment to temperature | G18: 1 | H18: 1 | I18: 5 | J18: =IF(MAX(G18:I18)=0,"",MAX(G18:I18)) -> 5 | K18: 1 | L18: =IFERROR(J18*K18,"") -> 5 | M18: Adequate air-conditioning units operates 24/7 daily to provide optimum operating temperatures. | N18: Selection of controls | O18: Operating Procedures for Information and Communication Technology (ISMS-14) | Q18: Implemented
D19: equipment failure | E19: sensitivity of equipment to voltage change | G19: 1 | H19: 1 | I19: 5 | J19: =IF(MAX(G19:I19)=0,"",MAX(G19:I19)) -> 5 | K19: 1 | L19: =IFERROR(J19*K19,"") -> 5 | M19: Power supply to racks are supplied by circuits with appropriate power stabilizers and controllers; that are suitable for use in data centre electrical power supply systems. | N19: Selection of controls | O19: Operating Procedures for Information and Communication Technology (ISMS-14) | Q19: Implemented
D20: fire | E20: location sensitive to natural disasters | F20: =IF($C20<>"",C20,"") | G20: 1 | H20: 1 | I20: 5 | J20: =IF(MAX(G20:I20)=0,"",MAX(G20:I20)) -> 5 | K20: 1 | L20: =IFERROR(J20*K20,"") -> 5 | M20: Fire protection systems are implemented and maintained according to FSB requirements; fire extinguishers and hose reels are placed in common areas. Servers in the data centre are protected by gas and water fire suppression protection systems. | N20: Risk acceptance | O20: Risk Assessment and Treatment Methodology (ISMS-02) | Q20: Annual review
D21: interruption of power supply | E21: sensitivity of equipment to voltage change | F21: =IF($C21<>"",C21,"") | G21: 1 | H21: 1 | I21: 5 | J21: =IF(MAX(G21:I21)=0,"",MAX(G21:I21)) -> 5 | K21: 1 | L21: =IFERROR(J21*K21,"") -> 5 | M21: Building electrical power supply system and sources are reliable. Data centre also has backup generator and UPS systems to prevent blackouts. | N21: Risk acceptance | O21: Risk Assessment and Treatment Methodology (ISMS-02) | Q21: Annual review
D22: misuse of information systems | E22: inadequate supervision of external suppliers | F22: =IF($C22<>"",C22,"") | G22: 5 | H22: 5 | I22: 5 | J22: =IF(MAX(G22:I22)=0,"",MAX(G22:I22)) -> 5 | K22: 1 | L22: =IFERROR(J22*K22,"") -> 5 | M22: Adequate IS policy, procedures and controls are implemented. Only pre-authorised technicians, engineers and other staff will be granted access to sensitive areas. | N22: Selection of controls | O22: Information Security Policy (ISMS-01) | Q22: Implemented
D23: application errors | E23: inadequate change control | G23: 1 | H23: 1 | I23: 5 | J23: =IF(MAX(G23:I23)=0,"",MAX(G23:I23)) -> 5 | K23: 1 | L23: =IFERROR(J23*K23,"") -> 5 | M23: Updates and patches are tested by pre-authorised technicians or engineers. These are applied only after they are tested in the vendors' test environment. | N23: Selection of controls | O23: Secure Development Policy (ISMS-07) | Q23: Implemented
A24: 3 | B24: eCom service | C24: PD | D24: hacking or virus attack | E24: Sensitive information will be available or accessible to unauthorized persons. Hackers may seize control of confidential data and information; using it to commit fraud and crimes. The system configuration and database may also be damaged or destroyed (loss). | F24: PD | G24: 5 | H24: 5 | I24: 5 | J24: =IF(MAX(G24:I24)=0,"",MAX(G24:I24)) -> 5 | K24: 1 | L24: =IFERROR(J24*K24,"") -> 5 | M24: Anti-virus installed and regular updates for virus signatures and application upgrades. The server hardware is housed in an external data centre with access restricted to authorized personnel from the service provider, and data centre facilities operation staff. | N24: Selection of controls | O24: Procedures for Working in Secure Areas (ISMS-12) | Q24: Implemented
D25: equipment failure | E25: inadequate change control | F25: =IF($C25<>"",C25,"") | G25: 1 | H25: 1 | I25: 5 | J25: =IF(MAX(G25:I25)=0,"",MAX(G25:I25)) -> 5 | K25: 1 | L25: =IFERROR(J25*K25,"") -> 5 | M25: Updates and patches are tested by pre-authorised technicians or engineers. These are applied only after they are tested in the vendors' test environment. | N25: Selection of controls | O25: Operating Procedures for Information and Communication Technology (ISMS-14) | Q25: Implemented
D26: equipment failure | E26: inadequate maintenance | F26: =IF($C26<>"",C26,"") | G26: 1 | H26: 1 | I26: 5 | J26: =IF(MAX(G26:I26)=0,"",MAX(G26:I26)) -> 5 | K26: 1 | L26: =IFERROR(J26*K26,"") -> 5 | M26: Regular maintenance is carried out on the server hardware, operating system software, and application software. Preventive and corrective maintenance are carried out as per manufacturers' recommendations. | N26: Selection of controls | O26: Operating Procedures for Information and Communication Technology (ISMS-14) | Q26: Implemented
D27: equipment failure | E27: location sensitive to water leakage | G27: 1 | H27: 1 | I27: 5 | J27: =IF(MAX(G27:I27)=0,"",MAX(G27:I27)) -> 5 | K27: 1 | L27: =IFERROR(J27*K27,"") -> 5 | M27: Server is located in a secure 3rd party data centre; i.e. no piping inside or around the area. | N27: Selection of controls | O27: Operating Procedures for Information and Communication Technology (ISMS-14) | Q27: Implemented
D28: equipment failure | E28: sensitivity of equipment to temperature | G28: 1 | H28: 1 | I28: 5 | J28: =IF(MAX(G28:I28)=0,"",MAX(G28:I28)) -> 5 | K28: 1 | L28: =IFERROR(J28*K28,"") -> 5 | M28: Server is housed in a 3rd party data centre with adequate air quality and temperature control systems; which operates 24/7 daily to provide optimum operating temperatures. | N28: Selection of controls | O28: Operating Procedures for Information and Communication Technology (ISMS-14) | Q28: Implemented
D29: equipment failure | E29: sensitivity of equipment to voltage change | G29: 1 | H29: 1 | I29: 5 | J29: =IF(MAX(G29:I29)=0,"",MAX(G29:I29)) -> 5 | K29: 1 | L29: =IFERROR(J29*K29,"") -> 5 | M29: Power supply to racks are supplied by circuits with power stabilizers and controllers. | N29: Risk acceptance | O29: Risk Assessment and Treatment Methodology (ISMS-02) | Q29: Annual review
D30: fire | E30: location sensitive to natural disasters | F30: =IF($C30<>"",C30,"") | G30: 1 | H30: 1 | I30: 5 | J30: =IF(MAX(G30:I30)=0,"",MAX(G30:I30)) -> 5 | K30: 1 | L30: =IFERROR(J30*K30,"") -> 5 | M30: Fire protection according to FSB requirements; fire extinguishers and hose reels are placed in common areas. Servers in the data centre are protected by gas and water fire suppression protection systems. | N30: Risk acceptance | O30: Risk Assessment and Treatment Methodology (ISMS-02) | Q30: Annual review
D31: interruption of power supply | E31: sensitivity of equipment to voltage change | F31: =IF($C31<>"",C31,"") | G31: 1 | H31: 1 | I31: 5 | J31: =IF(MAX(G31:I31)=0,"",MAX(G31:I31)) -> 5 | K31: 1 | L31: =IFERROR(J31*K31,"") -> 5 | M31: Building electrical power supply system and sources are reliable. Data centre also has backup generator and UPS systems to prevent suddent power trips and blackouts. | N31: Selection of controls | O31: Risk Assessment and Treatment Methodology (ISMS-02) | Q31: Annual review
D32: misuse of information systems | E32: inadequate level of knowledge and/or awareness of employees | F32: =IF($C32<>"",C32,"") | G32: 5 | H32: 1 | I32: 1 | J32: =IF(MAX(G32:I32)=0,"",MAX(G32:I32)) -> 5 | K32: 1 | L32: =IFERROR(J32*K32,"") -> 5 | M32: Logical and physical access to the server and network is restricted based on least privileged access needs. Unauthorised access is also prevented through anti virus and malware protection. | N32: Selection of controls | O32: Information Security Policy (ISMS-01) | Q32: Implemented
D33: misuse of information systems | E33: inadequate supervision of external suppliers | F33: =IF($C33<>"",C33,"") | G33: 5 | H33: 5 | I33: 5 | J33: =IF(MAX(G33:I33)=0,"",MAX(G33:I33)) -> 5 | K33: 1 | L33: =IFERROR(J33*K33,"") -> 5 | M33: Adequate IS policy, procedures and controls are implemented. Only pre-authorised technicians, engineers and other staff will be granted access to sensitive areas. | N33: Selection of controls | O33: Supplier Security Policy (ISMS-08) | Q33: Implemented
A36: 4 | B36: PCs (OA) | C36: Staff | D36: hacking or virus attack | E36: Confidential information will available to unauthorized persons. Integrity of confidential information and intellectual property may be compromised. | F36: PD | G36: 5 | H36: 5 | I36: 5 | J36: =IF(MAX(G36:I36)=0,"",MAX(G36:I36)) -> 5 | K36: 1 | L36: =IFERROR(J36*K36,"") -> 5 | M36: Anti-virus installed and regular updates for virus signatures and application upgrades. | N36: Selection of controls | O36: Determine and "plug" weaknesses via VAPT | P36: CEO | Q36: WIP | R36: 43445
D37: malicious code | E37: inadequate change control | F37: =IF($C37<>"",C37,"") | G37: 1 | H37: 1 | I37: 5 | J37: =IF(MAX(G37:I37)=0,"",MAX(G37:I37)) -> 5 | K37: 1 | L37: =IFERROR(J37*K37,"") -> 5 | M37: Application and system updates are tested separately before they are rolled out to staff. | N37: Selection of controls | O37: Operating Procedures for Information and Communication Technology (ISMS-14) | Q37: Implemented
D38: equipment failure | E38: inadequate maintenance | F38: =IF($C38<>"",C38,"") | G38: 1 | H38: 1 | I38: 5 | J38: =IF(MAX(G38:I38)=0,"",MAX(G38:I38)) -> 5 | K38: 1 | L38: =IFERROR(J38*K38,"") -> 5 | M38: Regular maintenance on PCs. | N38: Selection of controls | O38: Operating Procedures for Information and Communication Technology (ISMS-14) | Q38: Implemented
D39: equipment failure | E39: location sensitive to water leakage | G39: 1 | H39: 1 | I39: 5 | J39: =IF(MAX(G39:I39)=0,"",MAX(G39:I39)) -> 5 | K39: 1 | L39: =IFERROR(J39*K39,"") -> 5 | M39: Workstations for staff are not located near or under any water pipes. | N39: Selection of controls | O39: Operating Procedures for Information and Communication Technology (ISMS-14) | Q39: Implemented
D40: equipment failure | E40: sensitivity of equipment to temperature | G40: 1 | H40: 1 | I40: 5 | J40: =IF(MAX(G40:I40)=0,"",MAX(G40:I40)) -> 5 | K40: 1 | L40: =IFERROR(J40*K40,"") -> 5 | M40: All laptop and desktop PCs function normally, and are prevented from overheating; as the cooling fans for each system is functioning properly. In addition, the office room temperature is adequately maintained, and suitable for office work. | N40: Selection of controls | O40: Operating Procedures for Information and Communication Technology (ISMS-14) | Q40: Implemented
D41: equipment failure | E41: sensitivity of equipment to voltage change | G41: 1 | H41: 1 | I41: 5 | J41: =IF(MAX(G41:I41)=0,"",MAX(G41:I41)) -> 5 | K41: 1 | L41: =IFERROR(J41*K41,"") -> 5 | M41: The electrical power circuits in the office are stable and suitable to support normal operations for office equipment. | N41: Risk acceptance | O41: Operating Procedures for Information and Communication Technology (ISMS-14) | Q41: Implemented
D42: fire | E42: location sensitive to natural disasters | F42: =IF($C42<>"",C42,"") | G42: 1 | H42: 1 | I42: 5 | J42: =IF(MAX(G42:I42)=0,"",MAX(G42:I42)) -> 5 | K42: 1 | L42: =IFERROR(J42*K42,"") -> 5 | M42: fire protection according to FSB requirements; fire extinguishers and hose reels are placed in selected areas. | N42: Risk acceptance | O42: Risk Assessment and Treatment Methodology (ISMS-02) | Q42: Annual review
...

Sheet Applicability
A1: Clause Numbers | B1: Remarks
A2: 6.1.2 | B2: Information security risk assessment
A3: 6.1.3 | B3: Information security risk treatment

Sheet RA-RTP (2020)
A1: Risk Assessment | N1: Risk Treatment Plan
A2: No | B2: Asset name Asset type | C2: Asset owner | D2: Threat | E2: Vulnerability | F2: Risk owner | G2: Confiden-tiality | H2: Integrity | I2: Availability | J2: Impact Severity | K2: Likelihood | L2: Risk | M2: Existing controls | N2: Selection of options | O2: Implementation approach | P2: By Whom | Q2: Status | R2: Next Follow-up date
A3: 1 | B3: Email server (service) | C3: Staff | D3: hacking or virus attack | E3: Confidential information will available to unauthorized persons Email records or data may be modified (loss of data integrity) Email application service and database may be disrupted (unavailable) | F3: TL | G3: 5 | H3: 5 | I3: 5 | J3: =IF(MAX(G3:I3)=0,"",MAX(G3:I3)) -> 5 | K3: 1 | L3: =IFERROR(J3*K3,"") -> 5 | M3: Anti-virus installed and regular updates for virus signatures and application upgrades. | N3: Selection of controls | O3: Conduct VAPT; determine and close weaknesses (if any) | P3: PD | Q3: Monitor
D4: application errors | E4: inadequate change control | F4: =IF($C4<>"",C4,"") | G4: 1 | H4: 1 | I4: 5 | J4: =IF(MAX(G4:I4)=0,"",MAX(G4:I4)) -> 5 | K4: 1 | L4: =IFERROR(J4*K4,"") -> 5 | M4: Critical updates and patches are tested by the vendor; then they are applied to the email server. | N4: Selection of controls | O4: Secure Development Policy (ISMS-07) | Q4: Implemented
D5: equipment failure | E5: inadequate maintenance | F5: =IF($C5<>"",C5,"") | G5: 1 | H5: 1 | I5: 5 | J5: =IF(MAX(G5:I5)=0,"",MAX(G5:I5)) -> 5 | K5: 1 | L5: =IFERROR(J5*K5,"") -> 5 | M5: Regular maintenance on essential IT and technology equipment. Implement ICT DR server for email. | N5: Selection of controls | O5: Operating Procedures for Information and Communication Technology (ISMS-14) | Q5: Implemented
D6: equipment failure | E6: location sensitive to water leakage | G6: 1 | H6: 1 | I6: 5 | J6: =IF(MAX(G6:I6)=0,"",MAX(G6:I6)) -> 5 | K6: 1 | L6: =IFERROR(J6*K6,"") -> 5 | M6: Ensure server rooms do not have water pipes running through or near by the server room; except fire protection system that is approved for data centre operations. | N6: Selection of controls | O6: Operating Procedures for Information and Communication Technology (ISMS-14) | Q6: Implemented
D7: equipment failure | E7: sensitivity of equipment to temperature | G7: 1 | H7: 1 | I7: 5 | J7: =IF(MAX(G7:I7)=0,"",MAX(G7:I7)) -> 5 | K7: 1 | L7: =IFERROR(J7*K7,"") -> 5 | M7: Computer server rooms have adequate air-conditioning units operating 24/7 daily. | N7: Selection of controls | O7: Operating Procedures for Information and Communication Technology (ISMS-14) | Q7: Implemented
D8: equipment failure | E8: sensitivity of equipment to voltage change | G8: 1 | H8: 1 | I8: 5 | J8: =IF(MAX(G8:I8)=0,"",MAX(G8:I8)) -> 5 | K8: 1 | L8: =IFERROR(J8*K8,"") -> 5 | M8: Power supply to racks are supplied by circuits with power stabilizers and controllers that are suitable to support data centre electrical power systems. | N8: Selection of controls | O8: Operating Procedures for Information and Communication Technology (ISMS-14) | Q8: Implemented
D9: fire | E9: location sensitive to natural disasters | F9: =IF($C9<>"",C9,"") | G9: 1 | H9: 1 | I9: 5 | J9: =IF(MAX(G9:I9)=0,"",MAX(G9:I9)) -> 5 | K9: 1 | L9: =IFERROR(J9*K9,"") -> 5 | M9: Fire protection systems are implemented and maintained according to FSB requirements; including placement of fire extinguishers and hose reels in selected areas. Servers in the data centre are protected by gas and water fire suppression protection systems. | N9: Risk acceptance | O9: Risk Assessment and Treatment Methodology (ISMS-02) | Q9: Annual review
D10: interruption of power supply | E10: sensitivity of equipment to voltage change | F10: =IF($C10<>"",C10,"") | G10: 1 | H10: 1 | I10: 5 | J10: =IF(MAX(G10:I10)=0,"",MAX(G10:I10)) -> 5 | K10: 1 | L10: =IFERROR(J10*K10,"") -> 5 | M10: Building electrical power supply system and sources are reliable. Data centre also has backup generator and UPS systems to prevent blackouts. | N10: Risk acceptance | O10: Risk Assessment and Treatment Methodology (ISMS-02) | Q10: Annual review
D11: misuse of information systems | E11: inadequate level of knowledge and/or awareness of employees | F11: =IF($C11<>"",C11,"") | G11: 5 | H11: 1 | I11: 1 | J11: =IF(MAX(G11:I11)=0,"",MAX(G11:I11)) -> 5 | K11: 1 | L11: =IFERROR(J11*K11,"") -> 5 | M11: Adequate IS policy, procedures and controls are implemented – staff will be trained be made more aware of IS and cyberattacks. | N11: Selection of controls | O11: Information Security Policy (ISMS-01) | Q11: Implemented
D12: misuse of information systems | E12: inadequate supervision of external suppliers | F12: =IF($C12<>"",C12,"") | G12: 5 | H12: 5 | I12: 5 | J12: =IF(MAX(G12:I12)=0,"",MAX(G12:I12)) -> 5 | K12: 1 | L12: =IFERROR(J12*K12,"") -> 5 | M12: Adequate IS policy, procedures and controls are implemented. Only pre-authorised technicians, engineers and other staff will be granted access to sensitive areas. | N12: Selection of controls | O12: Supplier Security Policy (ISMS-08) | Q12: Implemented
D13: deterioration of media | E13: email records may be lost or corrupted | F13: =IF($C13<>"",C13,"") | G13: 1 | H13: 1 | I13: 5 | J13: =IF(MAX(G13:I13)=0,"",MAX(G13:I13)) -> 5 | K13: 1 | L13: =IFERROR(J13*K13,"") -> 5 | M13: Storage for email records use RAID. Users are required to save critical information and files in the department shared folders. | N13: Selection of controls | O13: Operating Procedures for Information and Communication Technology (ISMS-14) | Q13: Implemented
D14: information interception | E14: Confidential information will available to unauthorized persons. Email records or data may be modified (loss of data integrity). Information obtained may be used to commit fraud or crimes. Stolen intellectual property may be used against the company or disadvantage the company in business deals. | F14: =IF($C14<>"",C14,"") | G14: 5 | H14: 5 | I14: 1 | J14: =IF(MAX(G14:I14)=0,"",MAX(G14:I14)) -> 5 | K14: 1 | L14: =IFERROR(J14*K14,"") -> 5 | M14: Confidential information and intellectual property transmitted file attachments in emails will be encrypted using standard zip tools with passwords; which will be transmitted separately. | N14: Selection of controls | O14: Policy on the Use of Cryptographic Controls (ISMS-09) | Q14: Implemented
A16: 4 | B16: Computers | C16: Staff | D16: hacking or virus attack | E16: Confidential information will available to unauthorized persons. Integrity of confidential information and intellectual property may be compromised. | F16: PD | G16: 5 | H16: 5 | I16: 5 | J16: =IF(MAX(G16:I16)=0,"",MAX(G16:I16)) -> 5 | K16: 1 | L16: =IFERROR(J16*K16,"") -> 5 | M16: Anti-virus installed and regular updates for virus signatures and application upgrades. | N16: Selection of controls | O16: Determine and "plug" weaknesses via VAPT | P16: Staff | Q16: Monitor
D17: malicious code | E17: inadequate change control | F17: =IF($C17<>"",C17,"") | G17: 1 | H17: 1 | I17: 5 | J17: =IF(MAX(G17:I17)=0,"",MAX(G17:I17)) -> 5 | K17: 1 | L17: =IFERROR(J17*K17,"") -> 5 | M17: Application and system updates are tested separately before they are rolled out to staff. | N17: Selection of controls | O17: Operating Procedures for Information and Communication Technology (ISMS-14) | Q17: Implemented
D18: equipment failure | E18: inadequate maintenance | F18: =IF($C18<>"",C18,"") | G18: 1 | H18: 1 | I18: 5 | J18: =IF(MAX(G18:I18)=0,"",MAX(G18:I18)) -> 5 | K18: 1 | L18: =IFERROR(J18*K18,"") -> 5 | M18: Regular maintenance on PCs. | N18: Selection of controls | O18: Operating Procedures for Information and Communication Technology (ISMS-14) | Q18: Implemented
D19: equipment failure | E19: location sensitive to water leakage | G19: 1 | H19: 1 | I19: 5 | J19: =IF(MAX(G19:I19)=0,"",MAX(G19:I19)) -> 5 | K19: 1 | L19: =IFERROR(J19*K19,"") -> 5 | M19: Workstations for staff are not located near or under any water pipes. | N19: Selection of controls | O19: Operating Procedures for Information and Communication Technology (ISMS-14) | Q19: Implemented
D20: equipment failure | E20: sensitivity of equipment to temperature | G20: 1 | H20: 1 | I20: 5 | J20: =IF(MAX(G20:I20)=0,"",MAX(G20:I20)) -> 5 | K20: 1 | L20: =IFERROR(J20*K20,"") -> 5 | M20: All laptop and desktop PCs function normally, and are prevented from overheating; as the cooling fans for each system is functioning properly. In addition, the office room temperature is adequately maintained, and suitable for office work. | N20: Selection of controls | O20: Operating Procedures for Information and Communication Technology (ISMS-14) | Q20: Implemented
D21: equipment failure | E21: sensitivity of equipment to voltage change | G21: 1 | H21: 1 | I21: 5 | J21: =IF(MAX(G21:I21)=0,"",MAX(G21:I21)) -> 5 | K21: 1 | L21: =IFERROR(J21*K21,"") -> 5 | M21: The electrical power circuits in the office are stable and suitable to support normal operations for office equipment. | N21: Risk acceptance | O21: Operating Procedures for Information and Communication Technology (ISMS-14) | Q21: Implemented
D22: fire | E22: location sensitive to natural disasters | F22: =IF($C22<>"",C22,"") | G22: 1 | H22: 1 | I22: 5 | J22: =IF(MAX(G22:I22)=0,"",MAX(G22:I22)) -> 5 | K22: 1 | L22: =IFERROR(J22*K22,"") -> 5 | M22: fire protection according to FSB requirements; fire extinguishers and hose reels are placed in selected areas. | N22: Risk acceptance | O22: Risk Assessment and Treatment Methodology (ISMS-02) | Q22: Annual review
D23: interruption of power supply | E23: sensitivity of equipment to voltage change | F23: =IF($C23<>"",C23,"") | G23: 1 | H23: 1 | I23: 5 | J23: =IF(MAX(G23:I23)=0,"",MAX(G23:I23)) -> 5 | K23: 1 | L23: =IFERROR(J23*K23,"") -> 5 | M23: Building electrical power supply system and sources are reliable. | N23: Risk acceptance | O23: Risk Assessment and Treatment Methodology (ISMS-02) | Q23: Annual review
D24: misuse of information systems | E24: inadequate level of knowledge and/or awareness of employees | F24: =IF($C24<>"",C24,"") | G24: 5 | H24: 1 | I24: 1 | J24: =IF(MAX(G24:I24)=0,"",MAX(G24:I24)) -> 5 | K24: 1 | L24: =IFERROR(J24*K24,"") -> 5 | M24: Adequate IS policy, procedures and controls are implemented – staff will be trained be made more aware of IS and cyberattacks. | N24: Selection of controls | O24: Information Security Policy (ISMS-01) | Q24: Implemented
D25: misuse of information systems | E25: inadequate supervision of external suppliers | F25: =IF($C25<>"",C25,"") | G25: 5 | H25: 5 | I25: 5 | J25: =IF(MAX(G25:I25)=0,"",MAX(G25:I25)) -> 5 | K25: 1 | L25: =IFERROR(J25*K25,"") -> 5 | M25: Adequate IS policy, procedures and controls are implemented. Only pre-authorised technicians, engineers and other staff will be granted access to sensitive areas. | N25: Selection of controls | O25: Supplier Security Policy (ISMS-08) | Q25: Implemented
D26: disclosure of passwords | E26: inadequate level of knowledge and/or awareness of employees | F26: =IF($C26<>"",C26,"") | G26: 5 | H26: 5 | I26: 1 | J26: =IF(MAX(G26:I26)=0,"",MAX(G26:I26)) -> 5 | K26: 1 | L26: =IFERROR(J26*K26,"") -> 5 | M26: Conduct appropriate IS training sessions to improve IS awareness and cultivate good IS practices. | N26: Selection of controls | O26: Information Security Policy (ISMS-01) | Q26: Implemented
D27: leakage/disclosure of information | E27: inadequate level of knowledge and/or awareness of employees | F27: =IF($C27<>"",C27,"") | G27: 5 | H27: 5 | I27: 1 | J27: =IF(MAX(G27:I27)=0,"",MAX(G27:I27)) -> 5 | K27: 1 | L27: =IFERROR(J27*K27,"") -> 5 | M27: Increase IS awareness and good pratices; like using standard zip tools with passwords to encrpyt confidential information and intellectual property transmitted file attachments in emails, and transmit passwords separately. | N27: Selection of controls | O27: Information Security Policy (ISMS-01) | Q27: Implemented
A28: 6 | B28: Router-Firewall (OA) | C28: PD | D28: hacking or virus attack | E28: Confidential information will available to unauthorized persons. Integrity of confidential information and intellectual property may be compromised. | F28: PD | G28: 5 | H28: 5 | I28: 5 | J28: =IF(MAX(G28:I28)=0,"",MAX(G28:I28)) -> 5 | K28: 1 | L28: =IFERROR(J28*K28,"") -> 5 | M28: Anti-virus installed and regular updates for virus signatures and application upgrades. | N28: Selection of controls | O28: VAPT will be conducted to determine gaps, and identify actions to plug weaknesses | P28: PD | Q28: Monitor
D29: malicious code | E29: inadequate change control | F29: =IF($C29<>"",C29,"") | G29: 1 | H29: 1 | I29: 5 | J29: =IF(MAX(G29:I29)=0,"",MAX(G29:I29)) -> 5 | K29: 1 | L29: =IFERROR(J29*K29,"") -> 5 | M29: Firewall firmware updates and patches are tested separately at the vendor's test environment before they are installed. | N29: Selection of controls | O29: Operating Procedures for Information and Communication Technology (ISMS-14) | Q29: Implemented
D30: equipment failure | E30: inadequate maintenance | F30: =IF($C30<>"",C30,"") | G30: 1 | H30: 1 | I30: 5 | J30: =IF(MAX(G30:I30)=0,"",MAX(G30:I30)) -> 5 | K30: 1 | L30: =IFERROR(J30*K30,"") -> 5 | M30: Regular maintenance for firewall hardware and software. | N30: Selection of controls | O30: Operating Procedures for Information and Communication Technology (ISMS-14) | Q30: Implemented
D31: equipment failure | E31: location sensitive to water leakage | G31: 1 | H31: 1 | I31: 5 | J31: =IF(MAX(G31:I31)=0,"",MAX(G31:I31)) -> 5 | K31: 1 | L31: =IFERROR(J31*K31,"") -> 5 | M31: Firewall is not located near or under any water pipes. | N31: Selection of controls | O31: Operating Procedures for Information and Communication Technology (ISMS-14) | Q31: Implemented
D32: equipment failure | E32: sensitivity of equipment to temperature | G32: 1 | H32: 1 | I32: 5 | J32: =IF(MAX(G32:I32)=0,"",MAX(G32:I32)) -> 5 | K32: 1 | L32: =IFERROR(J32*K32,"") -> 5 | M32: Firewall is located in server rooms which have adequate air-conditioning units operating 24/7 daily. | N32: Selection of controls | O32: Operating Procedures for Information and Communication Technology (ISMS-14) | Q32: Implemented
D33: equipment failure | E33: sensitivity of equipment to voltage change | G33: 1 | H33: 1 | I33: 5 | J33: =IF(MAX(G33:I33)=0,"",MAX(G33:I33)) -> 5 | K33: 1 | L33: =IFERROR(J33*K33,"") -> 5 | M33: Power supply to racks are supplied by circuits with industially proven power stabilizers and controllers. | N33: Selection of controls | O33: Operating Procedures for Information and Communication Technology (ISMS-14) | Q33: Implemented
D34: fire | E34: location sensitive to natural disasters | F34: =IF($C34<>"",C34,"") | G34: 1 | H34: 1 | I34: 5 | J34: =IF(MAX(G34:I34)=0,"",MAX(G34:I34)) -> 5 | K34: 1 | L34: =IFERROR(J34*K34,"") -> 5 | M34: fire protection according to FSB requirements; fire extinguishers and hose reels are placed in selected areas. | N34: Risk acceptance | O34: Risk Assessment and Treatment Methodology (ISMS-02) | Q34: Annual review
D35: interruption of power supply | E35: sensitivity of equipment to voltage change | F35: =IF($C35<>"",C35,"") | G35: 1 | H35: 1 | I35: 5 | J35: =IF(MAX(G35:I35)=0,"",MAX(G35:I35)) -> 5 | K35: 1 | L35: =IFERROR(J35*K35,"") -> 5 | M35: Building electrical power supply system and sources are reliable. | N35: Risk acceptance | O35: Risk Assessment and Treatment Methodology (ISMS-02) | Q35: Annual review
D36: damage incurred during penetration testing | E36: inadequate network management | F36: =IF($C36<>"",C36,"") | G36: 1 | H36: 1 | I36: 5 | J36: =IF(MAX(G36:I36)=0,"",MAX(G36:I36)) -> 5 | K36: 1 | L36: =IFERROR(J36*K36,"") -> 5 | M36: Experienced and qualified cyber specialists are carefully selected and engaged to conduct this test. | N36: Selection of controls | O36: Establish plan before conducting VAPT | Q36: Approved
D37: malicious code | E37: inadequate change control | F37: =IF($C37<>"",C37,"") | G37: 1 | H37: 1 | I37: 5 | J37: =IF(MAX(G37:I37)=0,"",MAX(G37:I37)) -> 5 | K37: 1 | L37: =IFERROR(J37*K37,"") -> 5 | M37: Patches and updates for firwall are tested in the vendor's test lab before they are rolled out. | N37: Selection of controls | O37: Operating Procedures for Information and Communication Technology (ISMS-14) | Q37: Implemented
D38: unauthorized network access | E38: inadequate supervision of external suppliers | F38: =IF($C38<>"",C38,"") | G38: 1 | H38: 1 | I38: 5 | J38: =IF(MAX(G38:I38)=0,"",MAX(G38:I38)) -> 5 | K38: 1 | L38: =IFERROR(J38*K38,"") -> 5 | M38: Vendor's engineers and technicians are carefully selected and pre-authorised to work on the firewall. | N38: Selection of controls | O38: Supplier Security Policy (ISMS-08) | Q38: Implemented
F39: =IF($C39<>"",C39,"") | J39: =IF(MAX(G39:I39)=0,"",MAX(G39:I39)) | L39: =IFERROR(J39*K39,"")
A40: 8 | B40: Cloud storage | C40: PD | D40: hacking or virus attack | E40: Confidential information will available to unauthorized persons. Integrity of confidential information and intellectual property may be compromised. | F40: PD | G40: 5 | H40: 5 | I40: 5 | J40: =IF(MAX(G40:I40)=0,"",MAX(G40:I40)) -> 5 | K40: 1 | L40: =IFERROR(J40*K40,"") -> 5 | M40: Anti-virus installed and regular updates for virus signatures and application upgrades. | N40: Selection of controls | O40: VAPT will be conducted to determine gaps, and identify actions to plug weaknesses | P40: PD | Q40: Monitor
D41: malicious code | E41: inadequate change control | F41: =IF($C41<>"",C41,"") | G41: 1 | H41: 1 | I41: 5 | J41: =IF(MAX(G41:I41)=0,"",MAX(G41:I41)) -> 5 | K41: 1 | L41: =IFERROR(J41*K41,"") -> 5 | M41: Firmware updates and patches are tested separately at the vendor's test environment before they are installed. | N41: Selection of controls | O41: Secure Development Policy (ISMS-07) | Q41: Implemented
...

Sheet Assets (2)
A1: Asset Name | B1: Description | C1: Row No. | D1: Risk No.
A2: Email server | B2: Email services and application | C2: =IFERROR(MATCH(A2,'RA-RTP'!$B$3:$B$1000,0),"no match") -> 1 | D2: =IFERROR(INDEX('RA-RTP'!$A$3:$A$1000,MATCH(A2,'RA-RTP'!$B$3:$B$1000,0)),"no match") -> 1
A3: BMS main server | B3: Business control system server | C3: =IFERROR(MATCH(A3,'RA-RTP'!$B$3:$B$1000,0),"no match") -> 13 | D3: =IFERROR(INDEX('RA-RTP'!$A$3:$A$1000,MATCH(A3,'RA-RTP'!$B$3:$B$1000,0)),"no match") -> 2
A4: BMS workstation | B4: Business control monitoring station (NOC) | C4: =IFERROR(MATCH(A4,'RA-RTP'!$B$3:$B$1000,0),"no match") -> 24 | D4: =IFERROR(INDEX('RA-RTP'!$A$3:$A$1000,MATCH(A4,'RA-RTP'!$B$3:$B$1000,0)),"no match") -> 3
A5: Office Work PC | B5: Desktop or notebook PCs for office administration | C5: =IFERROR(MATCH(A5,'RA-RTP'!$B$3:$B$1000,0),"no match") -> 36 | D5: =IFERROR(INDEX('RA-RTP'!$A$3:$A$1000,MATCH(A5,'RA-RTP'!$B$3:$B$1000,0)),"no match") -> 4
A6: Firewall | B6: Main firewall | C6: =IFERROR(MATCH(A6,'RA-RTP'!$B$3:$B$1000,0),"no match") -> 48 | D6: =IFERROR(INDEX('RA-RTP'!$A$3:$A$1000,MATCH(A6,'RA-RTP'!$B$3:$B$1000,0)),"no match") -> 5
A7: Router | B7: Core router and internet connection | C7: =IFERROR(MATCH(A7,'RA-RTP'!$B$3:$B$1000,0),"no match") -> 60 | D7: =IFERROR(INDEX('RA-RTP'!$A$3:$A$1000,MATCH(A7,'RA-RTP'!$B$3:$B$1000,0)),"no match") -> 6
A8: NAS | B8: Network attached storage | C8: =IFERROR(MATCH(A8,'RA-RTP'!$B$3:$B$1000,0),"no match") -> 72 | D8: =IFERROR(INDEX('RA-RTP'!$A$3:$A$1000,MATCH(A8,'RA-RTP'!$B$3:$B$1000,0)),"no match") -> 7
A9: ACS-CCTV server | B9: Security access control & CCTV system (server) | C9: =IFERROR(MATCH(A9,'RA-RTP'!$B$3:$B$1000,0),"no match") -> 84 | D9: =IFERROR(INDEX('RA-RTP'!$A$3:$A$1000,MATCH(A9,'RA-RTP'!$B$3:$B$1000,0)),"no match") -> 8
A10: ACS-CCTV core switch | B10: Core Switch for CCTV Camera and Card Acess | C10: =IFERROR(MATCH(A10,'RA-RTP'!$B$3:$B$1000,0),"no match") -> 96 | D10: =IFERROR(INDEX('RA-RTP'!$A$3:$A$1000,MATCH(A10,'RA-RTP'!$B$3:$B$1000,0)),"no match") -> 9
A11: Chiller System Server | B11: Chiller System Server | C11: =IFERROR(MATCH(A11,'RA-RTP'!$B$3:$B$1000,0),"no match") -> 108 | D11: =IFERROR(INDEX('RA-RTP'!$A$3:$A$1000,MATCH(A11,'RA-RTP'!$B$3:$B$1000,0)),"no match") -> 10
A12: ACS-CCTV POE switch | B12: POE Switch for CCTV Camera and Card Acess | C12: =IFERROR(MATCH(A12,'RA-RTP'!$B$3:$B$1000,0),"no match") -> 120 | D12: =IFERROR(INDEX('RA-RTP'!$A$3:$A$1000,MATCH(A12,'RA-RTP'!$B$3:$B$1000,0)),"no match") -> 11
A13: EVMS server | B13: Visitor control system | C13: =IFERROR(MATCH(A13,'RA-RTP'!$B$3:$B$1000,0),"no match") -> 132 | D13: =IFERROR(INDEX('RA-RTP'!$A$3:$A$1000,MATCH(A13,'RA-RTP'!$B$3:$B$1000,0)),"no match") -> 12
... A30: Contractor staff | B30: Employees from M7 and other vendors or suppliers | C30: =IFERROR(MATCH(A30,'RA-RTP'!$B$3:$B$1000,0),"no match") -> no match | D30: =IFERROR(INDEX('RA-RTP'!$A$3:$A$1000,MATCH(A30,'RA-RTP'!$B$3:$B$1000,0)),"no match") -> no match
A31: Software applications | C31: =IFERROR(MATCH(A31,'RA-RTP'!$B$3:$B$1000,0),"no match") -> no match | D31: =IFERROR(INDEX('RA-RTP'!$A$3:$A$1000,MATCH(A31,'RA-RTP'!$B$3:$B$1000,0)),"no match") -> no match
A32: Database files and records | C32: =IFERROR(MATCH(A32,'RA-RTP'!$B$3:$B$1000,0),"no match") -> no match | D32: =IFERROR(INDEX('RA-RTP'!$A$3:$A$1000,MATCH(A32,'RA-RTP'!$B$3:$B$1000,0)),"no match") -> no match
A33: Infrastructure | B33: Other facilities (not listed in this table) | C33: =IFERROR(MATCH(A33,'RA-RTP'!$B$3:$B$1000,0),"no match") -> no match | D33: =IFERROR(INDEX('RA-RTP'!$A$3:$A$1000,MATCH(A33,'RA-RTP'!$B$3:$B$1000,0)),"no match") -> no match
A34: Outsourced processes & services | B34: Include M7 shared services support staff; vendor staff | C34: =IFERROR(MATCH(A34,'RA-RTP'!$B$3:$B$1000,0),"no match") -> no match | D34: =IFERROR(INDEX('RA-RTP'!$A$3:$A$1000,MATCH(A34,'RA-RTP'!$B$3:$B$1000,0)),"no match") -> no match

Sheet RA-RTP
A1: Risk Assessment | N1: Risk Treatment Plan
A2: No | B2: Asset name Asset type | C2: Asset owner | D2: Threat | E2: Vulnerability | F2: Risk owner | G2: Confiden-tiality | H2: Integrity | I2: Availability | J2: Impact Severity | K2: Likelihood | L2: Risk | M2: Existing controls | N2: Selection of options | O2: Implementation approach | P2: By Whom | Q2: Status | R2: Next Follow-up date
A3: 1 | B3: Email server | C3: CEO | D3: hacking or virus attack | E3: Confidential information will available to unauthorized persons Email records or data may be modified (loss of data integrity) Email application service and database may be disrupted (unavailable) | F3: CEO | G3: 5 | H3: 5 | I3: 5 | J3: =IF(MAX(G3:I3)=0,"",MAX(G3:I3)) -> 5 | K3: 1 | L3: =IFERROR(J3*K3,"") -> 5 | M3: Anti-virus installed and regular updates for virus signatures and application upgrades. | N3: Selection of controls | O3: Conduct VAPT; determine and close weaknesses (if any) | P3: CEO | Q3: Implemented | R3: 43445
D4: application errors | E4: inadequate change control | F4: =IF($C4<>"",C4,"") | G4: 1 | H4: 1 | I4: 5 | J4: =IF(MAX(G4:I4)=0,"",MAX(G4:I4)) -> 5 | K4: 1 | L4: =IFERROR(J4*K4,"") -> 5 | M4: Critical updates and patches are tested by the vendor; then they are applied to Dodid's email server. | N4: Selection of controls | O4: Secure Development Policy (ISMS-07) | Q4: Implemented
D5: equipment failure | E5: inadequate maintenance | F5: =IF($C5<>"",C5,"") | G5: 1 | H5: 1 | I5: 5 | J5: =IF(MAX(G5:I5)=0,"",MAX(G5:I5)) -> 5 | K5: 1 | L5: =IFERROR(J5*K5,"") -> 5 | M5: Regular maintenance on essential IT and technology equipment. Implement ICT DR server for email. | N5: Selection of controls | O5: Operating Procedures for Information and Communication Technology (ISMS-14) | Q5: Implemented
D6: equipment failure | E6: location sensitive to water leakage | G6: 1 | H6: 1 | I6: 5 | J6: =IF(MAX(G6:I6)=0,"",MAX(G6:I6)) -> 5 | K6: 1 | L6: =IFERROR(J6*K6,"") -> 5 | M6: Ensure server rooms do not have water pipes running through or near by. | N6: Selection of controls | O6: Operating Procedures for Information and Communication Technology (ISMS-14) | Q6: Implemented
D7: equipment failure | E7: sensitivity of equipment to temperature | G7: 1 | H7: 1 | I7: 5 | J7: =IF(MAX(G7:I7)=0,"",MAX(G7:I7)) -> 5 | K7: 1 | L7: =IFERROR(J7*K7,"") -> 5 | M7: Computer server rooms have adequate air-conditioning units operating 24/7 daily. | N7: Selection of controls | O7: Operating Procedures for Information and Communication Technology (ISMS-14) | Q7: Implemented
D8: equipment failure | E8: sensitivity of equipment to voltage change | G8: 1 | H8: 1 | I8: 5 | J8: =IF(MAX(G8:I8)=0,"",MAX(G8:I8)) -> 5 | K8: 1 | L8: =IFERROR(J8*K8,"") -> 5 | M8: Power supply to racks are supplied by circuits with industially proven power stabilizers and controllers. | N8: Selection of controls | O8: Operating Procedures for Information and Communication Technology (ISMS-14) | Q8: Implemented
D9: fire | E9: location sensitive to natural disasters | F9: =IF($C9<>"",C9,"") | G9: 1 | H9: 1 | I9: 5 | J9: =IF(MAX(G9:I9)=0,"",MAX(G9:I9)) -> 5 | K9: 1 | L9: =IFERROR(J9*K9,"") -> 5 | M9: fire protection according to FSB requirements; fire extinguishers and hose reels are placed in selected areas. Servers in the data centre are protected by gas and water fire suppression protection systems. | N9: Risk acceptance | O9: Risk Assessment and Treatment Methodology (ISMS-02) | Q9: Annual review
D10: interruption of power supply | E10: sensitivity of equipment to voltage change | F10: =IF($C10<>"",C10,"") | G10: 1 | H10: 1 | I10: 5 | J10: =IF(MAX(G10:I10)=0,"",MAX(G10:I10)) -> 5 | K10: 1 | L10: =IFERROR(J10*K10,"") -> 5 | M10: Building electrical power supply system and sources are reliable. Data centre also has backup generator and UPS systems to prevent blackouts. | N10: Risk acceptance | O10: Risk Assessment and Treatment Methodology (ISMS-02) | Q10: Annual review
D11: misuse of information systems | E11: inadequate level of knowledge and/or awareness of employees | F11: =IF($C11<>"",C11,"") | G11: 5 | H11: 1 | I11: 1 | J11: =IF(MAX(G11:I11)=0,"",MAX(G11:I11)) -> 5 | K11: 1 | L11: =IFERROR(J11*K11,"") -> 5 | M11: Adequate IS policy, procedures and controls are implemented – staff will be trained be made more aware of IS and cyberattacks. | N11: Selection of controls | O11: Information Security Policy (ISMS-01) | Q11: Implemented
D12: misuse of information systems | E12: inadequate supervision of external suppliers | F12: =IF($C12<>"",C12,"") | G12: 5 | H12: 5 | I12: 5 | J12: =IF(MAX(G12:I12)=0,"",MAX(G12:I12)) -> 5 | K12: 1 | L12: =IFERROR(J12*K12,"") -> 5 | M12: Adequate IS policy, procedures and controls are implemented. Only pre-authorised technicians, engineers and other staff will be granted access to sensitive areas. | N12: Selection of controls | O12: Supplier Security Policy (ISMS-08) | Q12: Implemented
D13: deterioration of media | E13: email records may be lost or corrupted | F13: =IF($C13<>"",C13,"") | G13: 1 | H13: 1 | I13: 5 | J13: =IF(MAX(G13:I13)=0,"",MAX(G13:I13)) -> 5 | K13: 1 | L13: =IFERROR(J13*K13,"") -> 5 | M13: Storage for email records use RAID. Users are required to save critical information and files in the department shared folders. | N13: Selection of controls | O13: Operating Procedures for Information and Communication Technology (ISMS-14) | Q13: Implemented
D14: information interception | E14: Confidential information will available to unauthorized persons. Email records or data may be modified (loss of data integrity). Information obtained may be used to commit fraud or crimes. Stolen intellectual property may be used against the company or disadvantage the company in business deals. | F14: =IF($C14<>"",C14,"") | G14: 5 | H14: 5 | I14: 1 | J14: =IF(MAX(G14:I14)=0,"",MAX(G14:I14)) -> 5 | K14: 1 | L14: =IFERROR(J14*K14,"") -> 5 | M14: Confidential information and intellectual property transmitted file attachments in emails will be encrypted using standard zip tools with passwords; which will be transmitted separately. | N14: Selection of controls | O14: Policy on the Use of Cryptographic Controls (ISMS-09) | Q14: Implemented
A15: 2 | B15: BMS main server | C15: HFM | D15: hacking or virus attack | E15: Sensitive information about the facilities will be available to unauthorized persons. Performance or status of fixed and movable assets may be modified. Hackers may seize control of critical fixed and movable assets connected to the BMS. The system configuration and database may also be damaged or destroyed (loss). | F15: FAM | G15: 5 | H15: 5 | I15: 5 | J15: =IF(MAX(G15:I15)=0,"",MAX(G15:I15)) -> 5 | K15: 1 | L15: =IFERROR(J15*K15,"") -> 5 | M15: Anti-virus installed and regular updates for virus signatures and application upgrades. BMS servers and PCs are connected via a dedicated network; that is not connected to the corporate (or office administration) LAN, and internet. | N15: Selection of controls | O15: Procedures for Working in Secure Areas (ISMS-12) | Q15: Implemented
D16: equipment failure | E16: inadequate maintenance | F16: =IF($C16<>"",C16,"") | G16: 1 | H16: 1 | I16: 5 | J16: =IF(MAX(G16:I16)=0,"",MAX(G16:I16)) -> 5 | K16: 1 | L16: =IFERROR(J16*K16,"") -> 5 | M16: Regular maintenance is carried out on the BMS server. | N16: Selection of controls | O16: Operating Procedures for Information and Communication Technology (ISMS-14) | Q16: Implemented
D17: equipment failure | E17: location sensitive to water leakage | G17: 1 | H17: 1 | I17: 5 | J17: =IF(MAX(G17:I17)=0,"",MAX(G17:I17)) -> 5 | K17: 1 | L17: =IFERROR(J17*K17,"") -> 5 | M17: BMS server is located in the NER; i.e. no piping inside or around the area. | N17: Selection of controls | O17: Operating Procedures for Information and Communication Technology (ISMS-14) | Q17: Implemented
D18: equipment failure | E18: sensitivity of equipment to temperature | G18: 1 | H18: 1 | I18: 5 | J18: =IF(MAX(G18:I18)=0,"",MAX(G18:I18)) -> 5 | K18: 1 | L18: =IFERROR(J18*K18,"") -> 5 | M18: Adequate air-conditioning units operates 24/7 daily to provide optimum operating temperatures. | N18: Selection of controls | O18: Operating Procedures for Information and Communication Technology (ISMS-14) | Q18: Implemented
D19: equipment failure | E19: sensitivity of equipment to voltage change | G19: 1 | H19: 1 | I19: 5 | J19: =IF(MAX(G19:I19)=0,"",MAX(G19:I19)) -> 5 | K19: 1 | L19: =IFERROR(J19*K19,"") -> 5 | M19: Power supply to racks are supplied by circuits with industrially proven power stabilizers and controllers. | N19: Selection of controls | O19: Operating Procedures for Information and Communication Technology (ISMS-14) | Q19: Implemented
D20: fire | E20: location sensitive to natural disasters | F20: =IF($C20<>"",C20,"") | G20: 1 | H20: 1 | I20: 5 | J20: =IF(MAX(G20:I20)=0,"",MAX(G20:I20)) -> 5 | K20: 1 | L20: =IFERROR(J20*K20,"") -> 5 | M20: Fire protection according to FSB requirements; fire extinguishers and hose reels are placed in common areas. Servers in the data centre are protected by gas and water fire suppression protection systems. | N20: Risk acceptance | O20: Risk Assessment and Treatment Methodology (ISMS-02) | Q20: Annual review
D21: interruption of power supply | E21: sensitivity of equipment to voltage change | F21: =IF($C21<>"",C21,"") | G21: 1 | H21: 1 | I21: 5 | J21: =IF(MAX(G21:I21)=0,"",MAX(G21:I21)) -> 5 | K21: 1 | L21: =IFERROR(J21*K21,"") -> 5 | M21: Building electrical power supply system and sources are reliable. Data centre also has backup generator and UPS systems to prevent blackouts. | N21: Risk acceptance | O21: Risk Assessment and Treatment Methodology (ISMS-02) | Q21: Annual review
D22: misuse of information systems | E22: inadequate level of knowledge and/or awareness of employees | F22: =IF($C22<>"",C22,"") | G22: 5 | H22: 1 | I22: 1 | J22: =IF(MAX(G22:I22)=0,"",MAX(G22:I22)) -> 5 | K22: 1 | L22: =IFERROR(J22*K22,"") -> 5 | M22: BMS is configured only to monitor the performance of the assets. Staff and vendors using the BMS are pre-authorised and trained. | N22: Selection of controls | O22: Information Security Policy (ISMS-01) | Q22: Implemented
D23: misuse of information systems | E23: inadequate supervision of external suppliers | F23: =IF($C23<>"",C23,"") | G23: 5 | H23: 5 | I23: 5 | J23: =IF(MAX(G23:I23)=0,"",MAX(G23:I23)) -> 5 | K23: 1 | L23: =IFERROR(J23*K23,"") -> 5 | M23: Adequate IS policy, procedures and controls are implemented. Only pre-authorised technicians, engineers and other staff will be granted access to sensitive areas. | N23: Selection of controls | O23: Information Security Policy (ISMS-01) | Q23: Implemented
D24: application errors | E24: inadequate change control | G24: 1 | H24: 1 | I24: 5 | J24: =IF(MAX(G24:I24)=0,"",MAX(G24:I24)) -> 5 | K24: 1 | L24: =IFERROR(J24*K24,"") -> 5 | M24: Updates and patches are tested by pre-authorised technicians or engineers. These are applied only after they are tested in the vendors' test environment. | N24: Selection of controls | O24: Secure Development Policy (ISMS-07) | Q24: Implemented
A26: 3 | B26: BMS workstation | C26: HFM | D26: hacking or virus attack | E26: Sensitive information about the facilities will be available to unauthorized persons. Performance or status of fixed and movable assets may be modified. Hackers may seize control of critical fixed and movable assets connected to the BMS. The system configuration and database may also be damaged or destroyed (loss). | F26: FAM | G26: 5 | H26: 5 | I26: 5 | J26: =IF(MAX(G26:I26)=0,"",MAX(G26:I26)) -> 5 | K26: 1 | L26: =IFERROR(J26*K26,"") -> 5 | M26: Anti-virus installed and regular updates for virus signatures and application upgrades. BMS servers and PCs run on a separate network; that is not connected to the corporate (or office administration) LAN, and internet. | N26: Selection of controls | O26: Procedures for Working in Secure Areas (ISMS-12) | Q26: Implemented
D27: equipment failure | E27: inadequate change control | F27: =IF($C27<>"",C27,"") | G27: 1 | H27: 1 | I27: 5 | J27: =IF(MAX(G27:I27)=0,"",MAX(G27:I27)) -> 5 | K27: 1 | L27: =IFERROR(J27*K27,"") -> 5 | M27: Updates and patches are tested by pre-authorised technicians or engineers. These are applied only after they are tested in the vendors' test environment. | N27: Selection of controls | O27: Operating Procedures for Information and Communication Technology (ISMS-14) | Q27: Implemented
D28: equipment failure | E28: inadequate maintenance | F28: =IF($C28<>"",C28,"") | G28: 1 | H28: 1 | I28: 5 | J28: =IF(MAX(G28:I28)=0,"",MAX(G28:I28)) -> 5 | K28: 1 | L28: =IFERROR(J28*K28,"") -> 5 | M28: Regular maintenance is carried out on the BMS PC. | N28: Selection of controls | O28: Operating Procedures for Information and Communication Technology (ISMS-14) | Q28: Implemented
D29: equipment failure | E29: location sensitive to water leakage | G29: 1 | H29: 1 | I29: 5 | J29: =IF(MAX(G29:I29)=0,"",MAX(G29:I29)) -> 5 | K29: 1 | L29: =IFERROR(J29*K29,"") -> 5 | M29: BMS PC is located in the NOC; i.e. no piping inside or around the area. | N29: Selection of controls | O29: Operating Procedures for Information and Communication Technology (ISMS-14) | Q29: Implemented
D30: equipment failure | E30: sensitivity of equipment to temperature | G30: 1 | H30: 1 | I30: 5 | J30: =IF(MAX(G30:I30)=0,"",MAX(G30:I30)) -> 5 | K30: 1 | L30: =IFERROR(J30*K30,"") -> 5 | M30: Adequate air-conditioning units operates 24/7 daily to provide optimum operating temperatures. | N30: Selection of controls | O30: Operating Procedures for Information and Communication Technology (ISMS-14) | Q30: Implemented
D31: equipment failure | E31: sensitivity of equipment to voltage change | G31: 1 | H31: 1 | I31: 5 | J31: =IF(MAX(G31:I31)=0,"",MAX(G31:I31)) -> 5 | K31: 1 | L31: =IFERROR(J31*K31,"") -> 5 | M31: Power supply to racks are supplied by circuits with industrially proven power stabilizers and controllers. | N31: Risk acceptance | O31: Risk Assessment and Treatment Methodology (ISMS-02) | Q31: Annual review
D32: fire | E32: location sensitive to natural disasters | F32: =IF($C32<>"",C32,"") | G32: 1 | H32: 1 | I32: 5 | J32: =IF(MAX(G32:I32)=0,"",MAX(G32:I32)) -> 5 | K32: 1 | L32: =IFERROR(J32*K32,"") -> 5 | M32: Fire protection according to FSB requirements; fire extinguishers and hose reels are placed in common areas. Servers in the data centre are protected by gas and water fire suppression protection systems. | N32: Risk acceptance | O32: Risk Assessment and Treatment Methodology (ISMS-02) | Q32: Annual review
D33: interruption of power supply | E33: sensitivity of equipment to voltage change | F33: =IF($C33<>"",C33,"") | G33: 1 | H33: 1 | I33: 5 | J33: =IF(MAX(G33:I33)=0,"",MAX(G33:I33)) -> 5 | K33: 1 | L33: =IFERROR(J33*K33,"") -> 5 | M33: Building electrical power supply system and sources are reliable. Data centre also has backup generator and UPS systems to prevent blackouts. | N33: Selection of controls | O33: Risk Assessment and Treatment Methodology (ISMS-02) | Q33: Annual review
D34: misuse of information systems | E34: inadequate level of knowledge and/or awareness of employees | F34: =IF($C34<>"",C34,"") | G34: 5 | H34: 1 | I34: 1 | J34: =IF(MAX(G34:I34)=0,"",MAX(G34:I34)) -> 5 | K34: 1 | L34: =IFERROR(J34*K34,"") -> 5 | M34: BMS is configured only to monitor the performance of the assets. Staff and vendors using the BMS are pre-authorised and trained. | N34: Selection of controls | O34: Information Security Policy (ISMS-01) | Q34: Implemented
D35: misuse of information systems | E35: inadequate supervision of external suppliers | F35: =IF($C35<>"",C35,"") | G35: 5 | H35: 5 | I35: 5 | J35: =IF(MAX(G35:I35)=0,"",MAX(G35:I35)) -> 5 | K35: 1 | L35: =IFERROR(J35*K35,"") -> 5 | M35: Adequate IS policy, procedures and controls are implemented. Only pre-authorised technicians, engineers and other staff will be granted access to sensitive areas. | N35: Selection of controls | O35: Supplier Security Policy (ISMS-08) | Q35: Implemented
